<?xml version="1.0" encoding="UTF-8"?>
<!-- Generated by org.testng.reporters.JUnitReportReporter -->
<testsuite name="test_signIn.LoginWithValidCredentialUsingEmail_FAIL" tests="1" time="22.940" ignored="6" failures="1" timestamp="19 Jul 2020 16:20:40 GMT" skipped="0" hostname="DESKTOP-PFUQSED" errors="0">
  <testcase name="loginWithValidCredentialUsingEmailTest" time="22.940" classname="test_signIn.LoginWithValidCredentialUsingEmail_FAIL">
    <failure type="java.lang.AssertionError" message="expected [TalentTEK ConsultingZZZZ] but found [TalentTEK Consulting
Genius Level 1]">
      <![CDATA[java.lang.AssertionError: expected [TalentTEK ConsultingZZZZ] but found [TalentTEK Consulting
Genius Level 1]
	at org.testng.Assert.fail(Assert.java:94)
	at org.testng.Assert.failNotEquals(Assert.java:513)
	at org.testng.Assert.assertEqualsImpl(Assert.java:135)
	at org.testng.Assert.assertEquals(Assert.java:116)
	at org.testng.Assert.assertEquals(Assert.java:190)
	at org.testng.Assert.assertEquals(Assert.java:200)
	at test_signIn.LoginWithValidCredentialUsingEmail_FAIL.loginWithValidCredentialUsingEmailTest(LoginWithValidCredentialUsingEmail_FAIL.java:34)
	at sun.reflect.NativeMethodAccessorImpl.invoke0(Native Method)
	at sun.reflect.NativeMethodAccessorImpl.invoke(Unknown Source)
	at sun.reflect.DelegatingMethodAccessorImpl.invoke(Unknown Source)
	at java.lang.reflect.Method.invoke(Unknown Source)
	at org.testng.internal.MethodInvocationHelper.invokeMethod(MethodInvocationHelper.java:104)
	at org.testng.internal.Invoker.invokeMethod(Invoker.java:645)
	at org.testng.internal.Invoker.invokeTestMethod(Invoker.java:851)
	at org.testng.internal.Invoker.invokeTestMethods(Invoker.java:1177)
	at org.testng.internal.TestMethodWorker.invokeTestMethods(TestMethodWorker.java:129)
	at org.testng.internal.TestMethodWorker.run(TestMethodWorker.java:112)
	at org.testng.TestRunner.privateRun(TestRunner.java:756)
	at org.testng.TestRunner.run(TestRunner.java:610)
	at org.testng.SuiteRunner.runTest(SuiteRunner.java:387)
	at org.testng.SuiteRunner.runSequentially(SuiteRunner.java:382)
	at org.testng.SuiteRunner.privateRun(SuiteRunner.java:340)
	at org.testng.SuiteRunner.run(SuiteRunner.java:289)
	at org.testng.SuiteRunnerWorker.runSuite(SuiteRunnerWorker.java:52)
	at org.testng.SuiteRunnerWorker.run(SuiteRunnerWorker.java:86)
	at org.testng.TestNG.runSuitesSequentially(TestNG.java:1293)
	at org.testng.TestNG.runSuitesLocally(TestNG.java:1218)
	at org.testng.TestNG.runSuites(TestNG.java:1133)
	at org.testng.TestNG.run(TestNG.java:1104)
	at org.testng.remote.AbstractRemoteTestNG.run(AbstractRemoteTestNG.java:132)
	at org.testng.remote.RemoteTestNG.initAndRun(RemoteTestNG.java:236)
	at org.testng.remote.RemoteTestNG.main(RemoteTestNG.java:81)
]]>
    </failure>
  </testcase> <!-- loginWithValidCredentialUsingEmailTest -->
  <testcase name="tearDown" classname="base.Config">
    <skipped/>
  </testcase> <!-- tearDown -->
  <testcase name="tearDown" classname="base.Config">
    <skipped/>
  </testcase> <!-- tearDown -->
  <testcase name="tearDown" classname="base.Config">
    <skipped/>
  </testcase> <!-- tearDown -->
  <testcase name="startTestSuite" classname="base.Config">
    <skipped/>
  </testcase> <!-- startTestSuite -->
  <testcase name="startTestSuite" classname="base.Config">
    <skipped/>
  </testcase> <!-- startTestSuite -->
  <testcase name="startTestSuite" classname="base.Config">
    <skipped/>
  </testcase> <!-- startTestSuite -->
</testsuite> <!-- test_signIn.LoginWithValidCredentialUsingEmail_FAIL -->
